***********************************************************************************
2016-06-07 15:49:43
304.602535963 seconds
5.07670893272 minutes
0.0846118155453 hours
Traceback:
Traceback (most recent call last):
  File "ua395.py", line 251, in <module>
    print metahash
NameError: name 'metahash' is not defined
***********************************************************************************
2016-06-08 10:24:28
7.47722101212 seconds
0.124620350202 minutes
0.0020770058367 hours
Traceback:
Traceback (most recent call last):
  File "ua395.py", line 154, in <module>
    hashIndex = simplejson.loads(fp.read())
  File "/usr/local/lib/python2.7/dist-packages/simplejson/__init__.py", line 516, in loads
    return _default_decoder.decode(s)
  File "/usr/local/lib/python2.7/dist-packages/simplejson/decoder.py", line 370, in decode
    obj, end = self.raw_decode(s)
  File "/usr/local/lib/python2.7/dist-packages/simplejson/decoder.py", line 400, in raw_decode
    return self.scan_once(s, idx=_w(s, idx).end())
JSONDecodeError: Unterminated string starting at: line 1 column 114686 (char 114685)
***********************************************************************************
2016-06-09 14:48:40
17.9892241955 seconds
0.299820403258 minutes
0.00499700672097 hours
Traceback:
Error: existing Album records not found.***********************************************************************************
2016-06-09 14:53:06
284.078870058 seconds
4.7346478343 minutes
0.0789107972383 hours
Traceback:
Traceback (most recent call last):
  File "ua395.py", line 240, in <module>
    imagesFile.close()
  File "lxml.etree.pyx", line 3239, in lxml.etree.parse (src/lxml/lxml.etree.c:69955)
  File "parser.pxi", line 1748, in lxml.etree._parseDocument (src/lxml/lxml.etree.c:102066)
  File "parser.pxi", line 1774, in lxml.etree._parseDocumentFromURL (src/lxml/lxml.etree.c:102330)
  File "parser.pxi", line 1678, in lxml.etree._parseDocFromFile (src/lxml/lxml.etree.c:101365)
  File "parser.pxi", line 1110, in lxml.etree._BaseParser._parseDocFromFile (src/lxml/lxml.etree.c:96817)
  File "parser.pxi", line 582, in lxml.etree._ParserContext._handleParseResultDoc (src/lxml/lxml.etree.c:91275)
  File "parser.pxi", line 683, in lxml.etree._handleParseResult (src/lxml/lxml.etree.c:92461)
  File "parser.pxi", line 620, in lxml.etree._raiseParseError (src/lxml/lxml.etree.c:91722)
IOError: Error reading file '/home/bcadmin/Desktop/Processing/ua395/stagingUA395/images.xml': failed to load external entity "/home/bcadmin/Desktop/Processing/ua395/stagingUA395/images.xml"
***********************************************************************************
2016-06-09 15:47:44
218.297370911 seconds
3.63828951518 minutes
0.0606381585863 hours
Traceback:
Traceback (most recent call last):
  File "ua395.py", line 249, in <module>
    input = ET.parse(os.path.join(stagingPath, "images.xml"), parser)
  File "lxml.etree.pyx", line 3239, in lxml.etree.parse (src/lxml/lxml.etree.c:69955)
  File "parser.pxi", line 1748, in lxml.etree._parseDocument (src/lxml/lxml.etree.c:102066)
  File "parser.pxi", line 1774, in lxml.etree._parseDocumentFromURL (src/lxml/lxml.etree.c:102330)
  File "parser.pxi", line 1678, in lxml.etree._parseDocFromFile (src/lxml/lxml.etree.c:101365)
  File "parser.pxi", line 1110, in lxml.etree._BaseParser._parseDocFromFile (src/lxml/lxml.etree.c:96817)
  File "parser.pxi", line 582, in lxml.etree._ParserContext._handleParseResultDoc (src/lxml/lxml.etree.c:91275)
  File "parser.pxi", line 683, in lxml.etree._handleParseResult (src/lxml/lxml.etree.c:92461)
  File "parser.pxi", line 620, in lxml.etree._raiseParseError (src/lxml/lxml.etree.c:91722)
IOError: Error reading file '/home/bcadmin/Desktop/Processing/ua395/stagingUA395/images.xml': failed to load external entity "/home/bcadmin/Desktop/Processing/ua395/stagingUA395/images.xml"
***********************************************************************************
2016-06-09 15:52:04
229.472212076 seconds
3.82453686794 minutes
0.0637422811323 hours
Traceback:
Traceback (most recent call last):
  File "ua395.py", line 392, in <module>
    for root, dirs, files in os.walk(folder):
  File "/usr/lib/python2.7/os.py", line 276, in walk
    names = listdir(top)
TypeError: coercing to Unicode: need string or buffer, lxml.etree._Element found
***********************************************************************************
2016-06-10 09:38:10
0.193724870682 seconds
0.0032287478447 minutes
5.38124640783e-05 hours
Traceback:
Traceback (most recent call last):
  File "ua395.py", line 248, in <module>
    shutil.copy2("images.xml", os.path.join("arrangment", "images" + startTimeReadable + ".xml"))
  File "/usr/lib/python2.7/shutil.py", line 130, in copy2
    copyfile(src, dst)
  File "/usr/lib/python2.7/shutil.py", line 83, in copyfile
    with open(dst, 'wb') as fdst:
IOError: [Errno 2] No such file or directory: 'arrangment/images2016-06-10_09-29-52.xml'
***********************************************************************************
2016-06-10 09:50:18
0.000292062759399 seconds
4.86771265666e-06 minutes
8.11285442776e-08 hours
Traceback:
Traceback (most recent call last):
  File "ua395.py", line 248, in <module>
    shutil.copy2("images.xml", os.path.join("arrangment", "images" + startTimeReadable + ".xml"))
  File "/usr/lib/python2.7/shutil.py", line 130, in copy2
    copyfile(src, dst)
  File "/usr/lib/python2.7/shutil.py", line 83, in copyfile
    with open(dst, 'wb') as fdst:
IOError: [Errno 2] No such file or directory: 'arrangment/images2016-06-10_09-44-05.xml'
***********************************************************************************
2016-06-10 11:42:47
5884.9907341 seconds
98.0831789017 minutes
1.63471964836 hours
Traceback:
Traceback (most recent call last):
  File "ua395.py", line 404, in <module>
    shutil.copy2("images.xml", os.path.join("baseDir", "arrangment"))
  File "/usr/lib/python2.7/shutil.py", line 130, in copy2
    copyfile(src, dst)
  File "/usr/lib/python2.7/shutil.py", line 83, in copyfile
    with open(dst, 'wb') as fdst:
IOError: [Errno 2] No such file or directory: 'baseDir/arrangment'
***********************************************************************************
2016-06-10 12:02:39
880.423002005 seconds
14.6737167001 minutes
0.244561945001 hours
Traceback:
Traceback (most recent call last):
  File "ua395.py", line 404, in <module>
    shutil.copy2("images.xml", os.path.join(baseDir, "arrangment"))
NameError: name 'baseDir' is not defined
***********************************************************************************
2016-06-10 12:35:12
738.361206055 seconds
12.3060201009 minutes
0.205100335015 hours
Traceback:
Traceback (most recent call last):
  File "ua395.py", line 405, in <module>
    os.rename(os.path.join("basePath", "arrangment", "images.xml"), "images" + startTimeFilename + ".xml")
OSError: [Errno 2] No such file or directory
***********************************************************************************
2016-06-10 13:36:19
312.177151918 seconds
5.20295253197 minutes
0.0867158755329 hours
Traceback:
Traceback (most recent call last):
  File "ua395.py", line 405, in <module>
    os.rename(os.path.join("basePath", "arrangement", "images.xml"), "images" + startTimeFilename + ".xml")
OSError: [Errno 2] No such file or directory
***********************************************************************************
2016-06-10 13:57:08
305.268368959 seconds
5.08780614932 minutes
0.0847967691554 hours
Traceback:
Traceback (most recent call last):
  File "ua395.py", line 406, in <module>
    os.rename(os.path.join("basePath", "arrangement", "images.xml"), "images" + startTimeFilename + ".xml")
OSError: [Errno 2] No such file or directory
***********************************************************************************
2016-06-10 14:17:20
337.147089958 seconds
5.61911816597 minutes
0.0936519694328 hours
Traceback:
Traceback (most recent call last):
  File "ua395.py", line 416, in <module>
    logText = logText + "\n" + totalSize + " bytes or " + readableSize + " downloaded"
TypeError: cannot concatenate 'str' and 'int' objects
***********************************************************************************
2016-06-28 12:24:59
9.27055907249 seconds
0.154509317875 minutes
0.00257515529792 hours
Traceback:
Traceback (most recent call last):
  File "ua395.py", line 163, in <module>
    passwordFile = open("password.txt", "w")
IOError: [Errno 13] Permission denied: 'password.txt'
***********************************************************************************
2016-06-28 12:27:49
72.9152441025 seconds
1.21525406837 minutes
0.0202542344729 hours
Traceback:
Traceback (most recent call last):
  File "ua395.py", line 204, in <module>
    r = requests.get(url, headers=headers)
  File "/usr/lib/python2.7/dist-packages/requests/api.py", line 55, in get
    return request('get', url, **kwargs)
  File "/usr/lib/python2.7/dist-packages/requests/api.py", line 44, in request
    return session.request(method=method, url=url, **kwargs)
  File "/usr/lib/python2.7/dist-packages/requests/sessions.py", line 455, in request
    resp = self.send(prep, **send_kwargs)
  File "/usr/lib/python2.7/dist-packages/requests/sessions.py", line 558, in send
    r = adapter.send(request, **kwargs)
  File "/usr/lib/python2.7/dist-packages/requests/adapters.py", line 330, in send
    timeout=timeout
  File "/usr/lib/python2.7/dist-packages/urllib3/connectionpool.py", line 562, in urlopen
    body=body, headers=headers)
  File "/usr/lib/python2.7/dist-packages/urllib3/connectionpool.py", line 414, in _make_request
    httplib_response = conn.getresponse(buffering=True)
  File "/usr/lib/python2.7/httplib.py", line 1051, in getresponse
    response.begin()
  File "/usr/lib/python2.7/httplib.py", line 415, in begin
    version, status, reason = self._read_status()
  File "/usr/lib/python2.7/httplib.py", line 371, in _read_status
    line = self.fp.readline(_MAXLINE + 1)
  File "/usr/lib/python2.7/socket.py", line 476, in readline
    data = self._sock.recv(self._rbufsize)
KeyboardInterrupt
***********************************************************************************
2016-06-28 12:40:31
523.959316015 seconds
8.73265526692 minutes
0.145544254449 hours
Traceback:
Traceback (most recent call last):
  File "ua395.py", line 404, in <module>
    if len(os.listdir(folder)) == 0:
OSError: [Errno 2] No such file or directory: 'StudentLife'
***********************************************************************************
2016-06-28 15:22:30
7.77066206932 seconds
0.129511034489 minutes
0.00215851724148 hours
Traceback:
Traceback (most recent call last):
  File "ua395.py", line 185, in <module>
    imagesXML = imageInput.getroot()
AttributeError: 'lxml.etree._Element' object has no attribute 'getroot'
***********************************************************************************
2016-06-28 15:50:38
248.48515892 seconds
4.14141931534 minutes
0.0690236552556 hours
Traceback:
Traceback (most recent call last):
  File "ua395.py", line 247, in <module>
    print "looking at " + str(albumElement.attrib("name"))
TypeError: 'lxml.etree._Attrib' object is not callable
***********************************************************************************
2016-06-28 16:13:23
456.226423025 seconds
7.60377371709 minutes
0.126729561951 hours
Traceback:
Traceback (most recent call last):
  File "ua395.py", line 247, in <module>
    print "looking at " + str(albumElement.attrib["name"])
UnicodeEncodeError: 'ascii' codec can't encode character u'\xe1' in position 17: ordinal not in range(128)
***********************************************************************************
2016-06-28 16:32:18
443.616284132 seconds
7.39360473553 minutes
0.123226745592 hours
Traceback:
Traceback (most recent call last):
  File "ua395.py", line 250, in <module>
    images.remove(albumElement)
NameError: name 'images' is not defined
